<?xml version="1.0" encoding="utf-8"?>
<!-- This URDF was automatically created by SolidWorks to URDF Exporter! Originally created by Stephen Brawner (brawner@gmail.com) 
     Commit Version: 1.5.1-0-g916b5db  Build Version: 1.5.7152.31018
     For more information, please see http://wiki.ros.org/sw_urdf_exporter -->
<robot
  name="zeus_arm">
  <link name="world"/>
   <joint name="fixed" type="fixed">
    <parent link="world"/>
    <child link="base_link"/>
   </joint>
  <link
    name="base_link">
    <inertial>
      <origin
        xyz="3.0908E-17 -3.2417E-17 0.062542"
        rpy="0 0 0" />
      <mass
        value="14.092" />
      <inertia
        ixx="0.085766"
        ixy="-4.3152E-32"
        ixz="2.8917E-17"
        iyy="0.085766"
        iyz="-2.1976E-17"
        izz="0.12286" />
    </inertial>
    <visual>
      <origin
        xyz="0 0 0"
        rpy="0 0 0" />
      <geometry>
        <mesh
          filename="package://zeus_arm/meshes/base_link_mat.STL" />
      </geometry>
      <material
        name="">
        <color
          rgba="1 1 1 1" />
      </material>
    </visual>
    <collision>
      <origin
        xyz="0 0 0"
        rpy="0 0 0" />
      <geometry>
        <mesh
          filename="package://zeus_arm/meshes/base_link_mat.STL" />
      </geometry>
    </collision>
  </link>
  <link
    name="base_plate">
    <inertial>
      <origin
        xyz="8.8979E-13 -0.013021 0.023608"
        rpy="0 0 0" />
      <mass
        value="2.982" />
      <inertia
        ixx="0.011454"
        ixy="-3.8197E-18"
        ixz="8.0334E-18"
        iyy="0.011983"
        iyz="0.00020792"
        izz="0.021582" />
    </inertial>
    <visual>
      <origin
        xyz="0 0 0"
        rpy="0 0 0" />
      <geometry>
        <mesh
          filename="package://zeus_arm/meshes/base_plate_mat.STL" />
      </geometry>
      <material
        name="">
        <color
          rgba="1 1 1 1" />
      </material>
    </visual>
    <collision>
      <origin
        xyz="0 0 0"
        rpy="0 0 0" />
      <geometry>
        <mesh
          filename="package://zeus_arm/meshes/base_plate_mat.STL" />
      </geometry>
    </collision>
  </link>
  <joint
    name="joint_1"
    type="continuous">
    <origin
      xyz="0 0 0.15254"
      rpy="0 0 0" />
    <parent
      link="base_link" />
    <child
      link="base_plate" />
    <axis
      xyz="0 0 1" />
    <limit
      effort="1000"
      velocity="2" />
  </joint>
  <link
    name="arm">
    <inertial>
      <origin
        xyz="8.0251E-14 0.3644 0.0039084"
        rpy="0 0 0" />
      <mass
        value="4.9582" />
      <inertia
        ixx="0.23974"
        ixy="1.3593E-16"
        ixz="-3.1522E-18"
        iyy="0.0026853"
        iyz="0.00079051"
        izz="0.24002" />
    </inertial>
    <visual>
      <origin
        xyz="0 0 0"
        rpy="0 0 0" />
      <geometry>
        <mesh
          filename="package://zeus_arm/meshes/arm_mat.STL" />
      </geometry>
      <material
        name="">
        <color
          rgba="1 1 1 1" />
      </material>
    </visual>
    <collision>
      <origin
        xyz="0 0 0"
        rpy="0 0 0" />
      <geometry>
        <mesh
          filename="package://zeus_arm/meshes/arm_mat.STL" />
      </geometry>
    </collision>
  </link>
  <joint
    name="joint_2"
    type="revolute">
    <origin
      xyz="0 0 0.06405"
      rpy="1.5708 0 0" />
    <parent
      link="base_plate" />
    <child
      link="arm" />
    <axis
      xyz="0 0 1" />
    <limit
      lower="-2.62"
      upper="2.62"
      effort="1000"
      velocity="2" />
    <dynamics
      damping="1"
      friction="3.0" />
  </joint>
  <link
    name="forearm">
    <inertial>
      <origin
        xyz="0.32992 -7.4353E-15 0.016597"
        rpy="0 0 0" />
      <mass
        value="5.1702" />
      <inertia
        ixx="0.0041396"
        ixy="3.3975E-16"
        ixz="0.00073797"
        iyy="0.16777"
        iyz="-9.622E-18"
        izz="0.16696" />
    </inertial>
    <visual>
      <origin
        xyz="0 0 0"
        rpy="0 0 0" />
      <geometry>
        <mesh
          filename="package://zeus_arm/meshes/forearm_mat.STL" />
      </geometry>
      <material
        name="">
        <color
          rgba="1 1 1 1" />
      </material>
    </visual>
    <collision>
      <origin
        xyz="0 0 0"
        rpy="0 0 0" />
      <geometry>
        <mesh
          filename="package://zeus_arm/meshes/forearm_mat.STL" />
      </geometry>
    </collision>
  </link>
  <joint
    name="joint_3"
    type="revolute">
    <origin
      xyz="0 0.73375 0"
      rpy="0 0 1.5708" />
    <parent
      link="arm" />
    <child
      link="forearm" />
    <axis
      xyz="0 0 1" />
    <limit
      lower="-2.62"
      upper="2.62"
      effort="1000"
      velocity="2" />
    <dynamics
      damping="1"
      friction="3.0" />
  </joint>
  <link
    name="wrist">
    <inertial>
      <origin
        xyz="0.083048 3.5977E-15 0.0090465"
        rpy="0 0 0" />
      <mass
        value="1.3369" />
      <inertia
        ixx="0.0013375"
        ixy="-3.8319E-19"
        ixz="-4.7176E-19"
        iyy="0.0018768"
        iyz="-8.1315E-20"
        izz="0.0020021" />
    </inertial>
    <visual>
      <origin
        xyz="0 0 0"
        rpy="0 0 0" />
      <geometry>
        <mesh
          filename="package://zeus_arm/meshes/wrist_mat.STL" />
      </geometry>
      <material
        name="">
        <color
          rgba="1 1 1 1" />
      </material>
    </visual>
    <collision>
      <origin
        xyz="0 0 0"
        rpy="0 0 0" />
      <geometry>
        <mesh
          filename="package://zeus_arm/meshes/wrist_mat.STL" />
      </geometry>
    </collision>
  </link>
  <joint
    name="joint_4"
    type="revolute">
    <origin
      xyz="0.5866 0 0"
      rpy="0 0 0" />
    <parent
      link="forearm" />
    <child
      link="wrist" />
    <axis
      xyz="0 0 1" />
    <limit
      lower="-2.62"
      upper="2.62"
      effort="1000"
      velocity="2" />
    <dynamics
      damping="1"
      friction="3.0" />
  </joint>
  <link
    name="gripper">
    <inertial>
      <origin
        xyz="1.2329E-06 9.5594E-06 0.010831"
        rpy="0 0 0" />
      <mass
        value="0.31021" />
      <inertia
        ixx="0.00016101"
        ixy="-1.6365E-09"
        ixz="-2.062E-09"
        iyy="0.00011567"
        iyz="3.2194E-09"
        izz="0.00011129" />
    </inertial>
    <visual>
      <origin
        xyz="0 0 0"
        rpy="0 0 0" />
      <geometry>
        <mesh
          filename="package://zeus_arm/meshes/gripper_mat.STL" />
      </geometry>
      <material
        name="">
        <color
          rgba="1 1 1 1" />
      </material>
    </visual>
    <collision>
      <origin
        xyz="0 0 0"
        rpy="0 0 0" />
      <geometry>
        <mesh
          filename="package://zeus_arm/meshes/gripper_mat.STL" />
      </geometry>
    </collision>
  </link>
  <joint
    name="joint_5"
    type="continuous">
    <origin
      xyz="0.15927 0 0.0137"
      rpy="-1.5708 0 -1.5708" />
    <parent
      link="wrist" />
    <child
      link="gripper" />
    <axis
      xyz="0 0 -1" />
    <limit
      lower="0"
      upper="0"
      effort="100"
      velocity="2" />
  </joint>

  <gazebo>
    <plugin name="gazebo_ros_control" filename="libgazebo_ros_control.so">
	<robotNameSpace>/zeus_arm</robotNameSpace>
    </plugin>
  </gazebo>


 <transmission name="tran1">
    <type>transmission_interface/SimpleTransmission</type>
    <joint name="joint_1">
      <hardwareInterface>hardware_interface/EffortJointInterface</hardwareInterface>
    </joint>
    <actuator name="motor1">
      <hardwareInterface>hardware_interface/EffortJointInterface</hardwareInterface>
      <mechanicalReduction>1</mechanicalReduction>
    </actuator>
  </transmission>

  <transmission name="tran2">
    <type>transmission_interface/SimpleTransmission</type>
    <joint name="joint_2">
      <hardwareInterface>hardware_interface/EffortJointInterface</hardwareInterface>
    </joint>
    <actuator name="motor2">
      <hardwareInterface>hardware_interface/EffortJointInterface</hardwareInterface>
      <mechanicalReduction>1</mechanicalReduction>
    </actuator>
  </transmission>

  <transmission name="tran3">
    <type>transmission_interface/SimpleTransmission</type>
    <joint name="joint_3">
      <hardwareInterface>hardware_interface/EffortJointInterface</hardwareInterface>
    </joint>
    <actuator name="motor3">
      <hardwareInterface>hardware_interface/EffortJointInterface</hardwareInterface>
      <mechanicalReduction>1</mechanicalReduction>
    </actuator>
  </transmission>

  <transmission name="tran4">
    <type>transmission_interface/SimpleTransmission</type>
    <joint name="joint_4">
      <hardwareInterface>hardware_interface/EffortJointInterface</hardwareInterface>
    </joint>
    <actuator name="motor4">
      <hardwareInterface>hardware_interface/EffortJointInterface</hardwareInterface>
      <mechanicalReduction>1</mechanicalReduction>
    </actuator>
  </transmission>

  <transmission name="tran5">
    <type>transmission_interface/SimpleTransmission</type>
    <joint name="joint_5">
      <hardwareInterface>hardware_interface/EffortJointInterface</hardwareInterface>
    </joint>
    <actuator name="motor5">
      <hardwareInterface>hardware_interface/EffortJointInterface</hardwareInterface>
      <mechanicalReduction>1</mechanicalReduction>
    </actuator>
  </transmission>
</robot>
